[2023-12-05 15:23:01,038] {taskinstance.py:1037} INFO - Dependencies all met for <TaskInstance: dag_with_scikit_learn_v03.get_matplotlib scheduled__2023-11-29T00:00:00+00:00 [queued]>
[2023-12-05 15:23:01,045] {taskinstance.py:1037} INFO - Dependencies all met for <TaskInstance: dag_with_scikit_learn_v03.get_matplotlib scheduled__2023-11-29T00:00:00+00:00 [queued]>
[2023-12-05 15:23:01,046] {taskinstance.py:1243} INFO - 
--------------------------------------------------------------------------------
[2023-12-05 15:23:01,046] {taskinstance.py:1244} INFO - Starting attempt 5 of 6
[2023-12-05 15:23:01,046] {taskinstance.py:1245} INFO - 
--------------------------------------------------------------------------------
[2023-12-05 15:23:01,057] {taskinstance.py:1264} INFO - Executing <Task(PythonOperator): get_matplotlib> on 2023-11-29 00:00:00+00:00
[2023-12-05 15:23:01,060] {standard_task_runner.py:52} INFO - Started process 12079 to run task
[2023-12-05 15:23:01,063] {standard_task_runner.py:76} INFO - Running: ['***', 'tasks', 'run', 'dag_with_scikit_learn_v03', 'get_matplotlib', 'scheduled__2023-11-29T00:00:00+00:00', '--job-id', '296', '--raw', '--subdir', 'DAGS_FOLDER/dag_with_python_dependencies.py', '--cfg-path', '/tmp/tmpasl4aj4b', '--error-file', '/tmp/tmplb49s5j2']
[2023-12-05 15:23:01,063] {standard_task_runner.py:77} INFO - Job 296: Subtask get_matplotlib
[2023-12-05 15:23:01,103] {logging_mixin.py:109} INFO - Running <TaskInstance: dag_with_scikit_learn_v03.get_matplotlib scheduled__2023-11-29T00:00:00+00:00 [running]> on host db75a6f967e6
[2023-12-05 15:23:01,185] {taskinstance.py:1431} INFO - Exporting the following env vars:
AIRFLOW_CTX_DAG_OWNER=Ali
AIRFLOW_CTX_DAG_ID=dag_with_scikit_learn_v03
AIRFLOW_CTX_TASK_ID=get_matplotlib
AIRFLOW_CTX_EXECUTION_DATE=2023-11-29T00:00:00+00:00
AIRFLOW_CTX_DAG_RUN_ID=scheduled__2023-11-29T00:00:00+00:00
[2023-12-05 15:23:01,186] {taskinstance.py:1718} ERROR - Task failed with exception
Traceback (most recent call last):
  File "/home/airflow/.local/lib/python3.7/site-packages/airflow/models/taskinstance.py", line 1334, in _run_raw_task
    self._execute_task_with_callbacks(context)
  File "/home/airflow/.local/lib/python3.7/site-packages/airflow/models/taskinstance.py", line 1460, in _execute_task_with_callbacks
    result = self._execute_task(context, self.task)
  File "/home/airflow/.local/lib/python3.7/site-packages/airflow/models/taskinstance.py", line 1516, in _execute_task
    result = execute_callable(context=context)
  File "/home/airflow/.local/lib/python3.7/site-packages/airflow/operators/python.py", line 174, in execute
    return_value = self.execute_callable()
  File "/home/airflow/.local/lib/python3.7/site-packages/airflow/operators/python.py", line 188, in execute_callable
    return self.python_callable(*self.op_args, **self.op_kwargs)
  File "/opt/airflow/dags/dag_with_python_dependencies.py", line 17, in get_matplotlib
    import matplotlib
ModuleNotFoundError: No module named 'matplotlib'
[2023-12-05 15:23:01,198] {taskinstance.py:1282} INFO - Marking task as UP_FOR_RETRY. dag_id=dag_with_scikit_learn_v03, task_id=get_matplotlib, execution_date=20231129T000000, start_date=20231205T152301, end_date=20231205T152301
[2023-12-05 15:23:01,210] {standard_task_runner.py:92} ERROR - Failed to execute job 296 for task get_matplotlib
Traceback (most recent call last):
  File "/home/airflow/.local/lib/python3.7/site-packages/airflow/task/task_runner/standard_task_runner.py", line 85, in _start_by_fork
    args.func(args, dag=self.dag)
  File "/home/airflow/.local/lib/python3.7/site-packages/airflow/cli/cli_parser.py", line 48, in command
    return func(*args, **kwargs)
  File "/home/airflow/.local/lib/python3.7/site-packages/airflow/utils/cli.py", line 92, in wrapper
    return f(*args, **kwargs)
  File "/home/airflow/.local/lib/python3.7/site-packages/airflow/cli/commands/task_command.py", line 298, in task_run
    _run_task_by_selected_method(args, dag, ti)
  File "/home/airflow/.local/lib/python3.7/site-packages/airflow/cli/commands/task_command.py", line 107, in _run_task_by_selected_method
    _run_raw_task(args, ti)
  File "/home/airflow/.local/lib/python3.7/site-packages/airflow/cli/commands/task_command.py", line 184, in _run_raw_task
    error_file=args.error_file,
  File "/home/airflow/.local/lib/python3.7/site-packages/airflow/utils/session.py", line 70, in wrapper
    return func(*args, session=session, **kwargs)
  File "/home/airflow/.local/lib/python3.7/site-packages/airflow/models/taskinstance.py", line 1334, in _run_raw_task
    self._execute_task_with_callbacks(context)
  File "/home/airflow/.local/lib/python3.7/site-packages/airflow/models/taskinstance.py", line 1460, in _execute_task_with_callbacks
    result = self._execute_task(context, self.task)
  File "/home/airflow/.local/lib/python3.7/site-packages/airflow/models/taskinstance.py", line 1516, in _execute_task
    result = execute_callable(context=context)
  File "/home/airflow/.local/lib/python3.7/site-packages/airflow/operators/python.py", line 174, in execute
    return_value = self.execute_callable()
  File "/home/airflow/.local/lib/python3.7/site-packages/airflow/operators/python.py", line 188, in execute_callable
    return self.python_callable(*self.op_args, **self.op_kwargs)
  File "/opt/airflow/dags/dag_with_python_dependencies.py", line 17, in get_matplotlib
    import matplotlib
ModuleNotFoundError: No module named 'matplotlib'
[2023-12-05 15:23:01,392] {local_task_job.py:154} INFO - Task exited with return code 1
[2023-12-05 15:23:01,425] {local_task_job.py:264} INFO - 0 downstream tasks scheduled from follow-on schedule check
